<?xml version="1.0" ?>
<sdf version="1.7">
  <model name="simple_rover">
    <!-- Main body: rectangular block -->
    <link name="chassis">
      <pose>0 0 0.1 0 0 0</pose>
      <inertial>
        <mass>1.0</mass>
      </inertial>
      <visual name="visual">
        <geometry>
          <box>
            <size>1.0 0.5 0.2</size>
          </box>
        </geometry>
        <material>
          <diffuse>1 0 0 1</diffuse>
        </material>
      </visual>
      <collision name="collision">
        <geometry>
          <box>
            <size>1.0 0.5 0.2</size>
          </box>
        </geometry>
      </collision>
    </link>

    <!-- Wheels: four cylinders -->
    <link name="left_front_wheel">
      <pose>0.4 0.3 0 0 1.5708 0</pose>
      <inertial>
        <mass>0.1</mass>
      </inertial>
      <visual name="visual">
        <geometry>
          <cylinder>
            <radius>0.1</radius>
            <length>0.05</length>
          </cylinder>
        </geometry>
        <material>
          <diffuse>0 0 1 1</diffuse>
        </material>
      </visual>
      <collision name="collision">
        <geometry>
          <cylinder>
            <radius>0.1</radius>
            <length>0.05</length>
          </cylinder>
        </geometry>
      </collision>
    </link>

    <link name="left_rear_wheel">
      <pose>-0.4 0.3 0 0 1.5708 0</pose>
      <inertial>
        <mass>0.1</mass>
      </inertial>
      <visual name="visual">
        <geometry>
          <cylinder>
            <radius>0.1</radius>
            <length>0.05</length>
          </cylinder>
        </geometry>
        <material>
          <diffuse>0 0 1 1</diffuse>
        </material>
      </visual>
      <collision name="collision">
        <geometry>
          <cylinder>
            <radius>0.1</radius>
            <length>0.05</length>
          </cylinder>
        </geometry>
      </collision>
    </link>

    <link name="right_front_wheel">
      <pose>0.4 -0.3 0 0 1.5708 0</pose>
      <inertial>
        <mass>0.1</mass>
      </inertial>
      <visual name="visual">
        <geometry>
          <cylinder>
            <radius>0.1</radius>
            <length>0.05</length>
          </cylinder>
        </geometry>
        <material>
          <diffuse>0 0 1 1</diffuse>
        </material>
      </visual>
      <collision name="collision">
        <geometry>
          <cylinder>
            <radius>0.1</radius>
            <length>0.05</length>
          </cylinder>
        </geometry>
      </collision>
    </link>

    <link name="right_rear_wheel">
      <pose>-0.4 -0.3 0 0 1.5708 0</pose>
      <inertial>
        <mass>0.1</mass>
      </inertial>
      <visual name="visual">
        <geometry>
          <cylinder>
            <radius>0.1</radius>
            <length>0.05</length>
          </cylinder>
        </geometry>
        <material>
          <diffuse>0 0 1 1</diffuse>
        </material>
      </visual>
      <collision name="collision">
        <geometry>
          <cylinder>
            <radius>0.1</radius>
            <length>0.05</length>
          </cylinder>
        </geometry>
      </collision>
    </link>

    <!-- Joints: connect wheels to chassis -->
    <joint name="left_front_wheel_joint" type="continuous">
      <parent>chassis</parent>
      <child>left_front_wheel</child>
      <axis>
        <xyz>0 1 0</xyz>
      </axis>
    </joint>
    <joint name="left_rear_wheel_joint" type="continuous">
      <parent>chassis</parent>
      <child>left_rear_wheel</child>
      <axis>
        <xyz>0 1 0</xyz>
      </axis>
    </joint>
    <joint name="right_front_wheel_joint" type="continuous">
      <parent>chassis</parent>
      <child>right_front_wheel</child>
      <axis>
        <xyz>0 1 0</xyz>
      </axis>
    </joint>
    <joint name="right_rear_wheel_joint" type="continuous">
      <parent>chassis</parent>
      <child>right_rear_wheel</child>
      <axis>
        <xyz>0 1 0</xyz>
      </axis>
    </joint>

    <!-- Differential Drive Plugin for ROS 2 Control -->
    <plugin name="diff_drive" filename="libgazebo_ros_diff_drive.so">
      <ros>
        <namespace>/rover</namespace>
      </ros>
      <left_joint>left_front_wheel_joint</left_joint>
      <left_joint>left_rear_wheel_joint</left_joint>
      <right_joint>right_front_wheel_joint</right_joint>
      <right_joint>right_rear_wheel_joint</right_joint>
      <wheel_separation>0.6</wheel_separation>
      <wheel_diameter>0.2</wheel_diameter>
      <max_wheel_torque>10</max_wheel_torque>
      <command_topic>cmd_vel</command_topic>
      <odometry_topic>odom</odometry_topic>
      <odometry_frame>odom</odometry_frame>
      <robot_base_frame>chassis</robot_base_frame>
    </plugin>
  </model>
</sdf>
